{"cells":[{"cell_type":"code","execution_count":null,"metadata":{"id":"uglutoR-RE_y"},"outputs":[],"source":["!pip install datasets\n","!pip install accelerate -U"]},{"cell_type":"code","execution_count":null,"metadata":{"id":"03y6_eBDWPYC"},"outputs":[],"source":["from google.colab import drive\n","import pandas as pd\n","import os\n","import json\n","import re\n","from datasets import Dataset\n","from torch.utils.data import DataLoader\n","from datasets import load_from_disk\n","from transformers import T5ForConditionalGeneration, T5Tokenizer, MT5ForConditionalGeneration, MT5Tokenizer\n","from transformers import Seq2SeqTrainingArguments\n","from transformers import DataCollatorForSeq2Seq\n","from transformers import Seq2SeqTrainer\n","os.environ['WANDB_SILENT']=\"true\"\n","os.environ[\"WANDB_DISABLED\"] = \"true\""]},{"cell_type":"code","execution_count":null,"metadata":{"colab":{"base_uri":"https://localhost:8080/"},"executionInfo":{"elapsed":2261,"status":"ok","timestamp":1701282141838,"user":{"displayName":"Md Zobaer Hossain","userId":"17306798615063951361"},"user_tz":-60},"id":"rRARV50sWsP1","outputId":"8ce3e7f5-5d23-4696-fb09-4a123f9a7311"},"outputs":[{"name":"stdout","output_type":"stream","text":["Drive already mounted at /content/drive; to attempt to forcibly remount, call drive.mount(\"/content/drive\", force_remount=True).\n"]}],"source":["drive.mount('/content/drive')\n","!cd /content/drive/MyDrive/Shared-Tasks/Num-Eval"]},{"cell_type":"code","execution_count":null,"metadata":{"colab":{"base_uri":"https://localhost:8080/"},"executionInfo":{"elapsed":11,"status":"ok","timestamp":1701282141839,"user":{"displayName":"Md Zobaer Hossain","userId":"17306798615063951361"},"user_tz":-60},"id":"T0LNwiAWRn-9","outputId":"ac497c5f-0b93-4150-bd3e-a4a0c93d9db7"},"outputs":[{"name":"stdout","output_type":"stream","text":["/content/drive/MyDrive/Shared-Tasks/Num-Eval\n"]}],"source":["cd /content/drive/MyDrive/Shared-Tasks/Num-Eval"]},{"cell_type":"code","execution_count":null,"metadata":{"id":"kduOrtFZavnU"},"outputs":[],"source":["from transformers import AutoTokenizer, AutoModelForSeq2SeqLM\n","model_id=\"google/flan-t5-base\"\n","tokenizer = AutoTokenizer.from_pretrained(model_id)\n","model = AutoModelForSeq2SeqLM.from_pretrained(model_id)"]},{"cell_type":"code","execution_count":null,"metadata":{"id":"hRlWbMIGaCzr"},"outputs":[],"source":["train_data = load_from_disk('./Dataset/train-drop-20k')\n","dev_data = load_from_disk('./Dataset/dev')"]},{"cell_type":"code","execution_count":null,"metadata":{"id":"uJt_j_TPeAlR"},"outputs":[],"source":["def collator(batch):\n","\n","    input = batch['t5-input'] #load original sentences\n","    label = batch['ans'] #load noisy sentences\n","    inputs = tokenizer(input, text_target=label, return_tensors=\"pt\", max_length = 512, padding='max_length',truncation=True) #tokenized sentences\n","\n","    return inputs"]},{"cell_type":"code","execution_count":null,"metadata":{"id":"oE4007INertV"},"outputs":[],"source":["train_tokenized = train_data.map(collator, remove_columns=train_data.column_names, batch_size=8, num_proc=4, batched=True)\n","dev_tokenized = dev_data.map(collator, remove_columns=dev_data.column_names, batch_size=8, num_proc=4, batched=True)\n"]},{"cell_type":"code","execution_count":null,"metadata":{"id":"K09dOulIfB3k"},"outputs":[],"source":["#define evaluation steps based on total dataset size\n","TRAIN_BATCH_SIZE = 2\n","EPOCHS = 3\n","LEARNING_RATE = 5e-5\n","data_size = len(train_tokenized)\n","EVAL_STEPS=int(data_size/(TRAIN_BATCH_SIZE*2))\n","SAVE_STEPS= EVAL_STEPS\n","\n","\n"]},{"cell_type":"code","execution_count":null,"metadata":{"colab":{"base_uri":"https://localhost:8080/"},"executionInfo":{"elapsed":3455,"status":"ok","timestamp":1701282150965,"user":{"displayName":"Md Zobaer Hossain","userId":"17306798615063951361"},"user_tz":-60},"id":"j_lLaNsBf8v4","outputId":"a42c40c2-1dfa-4acd-9636-e84fba815991"},"outputs":[{"name":"stderr","output_type":"stream","text":["Using the `WANDB_DISABLED` environment variable is deprecated and will be removed in v5. Use the --report_to flag to control the integrations used for logging result (for instance --report_to none).\n"]}],"source":["#define training argument object\n","training_args = Seq2SeqTrainingArguments(\n","  output_dir=\"./Outputs\",\n","  group_by_length=True,\n","  per_device_train_batch_size=TRAIN_BATCH_SIZE,\n","  gradient_accumulation_steps=2,\n","  evaluation_strategy=\"steps\",\n","  num_train_epochs=EPOCHS,\n","  fp16=False,\n","  save_steps=SAVE_STEPS,\n","  eval_steps=EVAL_STEPS,\n","  logging_steps=EVAL_STEPS,\n","  learning_rate=LEARNING_RATE,\n","  warmup_steps=100,\n","  save_total_limit=2,\n",")\n","\n","\n","#define training data collator\n","data_collator = DataCollatorForSeq2Seq(tokenizer, return_tensors='pt')\n","\n","\n","#define Seq2Seq Training object\n","trainer = Seq2SeqTrainer(\n","    model=model.cuda(),\n","    data_collator=data_collator,\n","    args=training_args,\n","    train_dataset=train_tokenized,\n","    eval_dataset=dev_tokenized,\n","    tokenizer=tokenizer\n",")"]},{"cell_type":"code","execution_count":null,"metadata":{"colab":{"background_save":true,"base_uri":"https://localhost:8080/","height":1000},"id":"wGWVkoeUgMsS","outputId":"1eafc6a1-2232-41ec-aea5-2fb874402dc0"},"outputs":[{"name":"stderr","output_type":"stream","text":["You're using a T5TokenizerFast tokenizer. Please note that with a fast tokenizer, using the `__call__` method is faster than using a method to encode the text followed by a call to the `pad` method to get a padded encoding.\n"]},{"data":{"text/html":["\n","    <div>\n","      \n","      <progress value='12790' max='38367' style='width:300px; height:20px; vertical-align: middle;'></progress>\n","      [12790/38367 4:31:45 < 9:03:31, 0.78 it/s, Epoch 1.00/3]\n","    </div>\n","    <table border=\"1\" class=\"dataframe\">\n","  <thead>\n"," <tr style=\"text-align: left;\">\n","      <th>Step</th>\n","      <th>Training Loss</th>\n","      <th>Validation Loss</th>\n","    </tr>\n","  </thead>\n","  <tbody>\n","  </tbody>\n","</table><p>"],"text/plain":["<IPython.core.display.HTML object>"]},"metadata":{},"output_type":"display_data"},{"name":"stderr","output_type":"stream","text":["ERROR:root:Internal Python error in the inspect module.\n","Below is the traceback from this internal error.\n","\n","ERROR:root:Internal Python error in the inspect module.\n","Below is the traceback from this internal error.\n","\n","ERROR:root:Internal Python error in the inspect module.\n","Below is the traceback from this internal error.\n","\n"]},{"name":"stdout","output_type":"stream","text":["Traceback (most recent call last):\n","  File \"/usr/local/lib/python3.10/dist-packages/IPython/core/interactiveshell.py\", line 3553, in run_code\n","    exec(code_obj, self.user_global_ns, self.user_ns)\n","  File \"<ipython-input-11-79cc5d5f2588>\", line 2, in <cell line: 2>\n","    trainer.train()\n","  File \"/usr/local/lib/python3.10/dist-packages/transformers/trainer.py\", line 1555, in train\n","    return inner_training_loop(\n","  File \"/usr/local/lib/python3.10/dist-packages/transformers/trainer.py\", line 1922, in _inner_training_loop\n","    self._maybe_log_save_evaluate(tr_loss, model, trial, epoch, ignore_keys_for_eval)\n","  File \"/usr/local/lib/python3.10/dist-packages/transformers/trainer.py\", line 2257, in _maybe_log_save_evaluate\n","    self.log(logs)\n","  File \"/usr/local/lib/python3.10/dist-packages/transformers/trainer.py\", line 2645, in log\n","    self.control = self.callback_handler.on_log(self.args, self.state, self.control, logs)\n","  File \"/usr/local/lib/python3.10/dist-packages/transformers/trainer_callback.py\", line 400, in on_log\n","    return self.call_event(\"on_log\", args, state, control, logs=logs)\n","  File \"/usr/local/lib/python3.10/dist-packages/transformers/trainer_callback.py\", line 407, in call_event\n","    result = getattr(callback, event)(\n","  File \"/usr/local/lib/python3.10/dist-packages/transformers/integrations/integration_utils.py\", line 653, in on_log\n","    self.tb_writer.flush()\n","  File \"/usr/local/lib/python3.10/dist-packages/torch/utils/tensorboard/writer.py\", line 1233, in flush\n","    writer.flush()\n","  File \"/usr/local/lib/python3.10/dist-packages/torch/utils/tensorboard/writer.py\", line 146, in flush\n","    self.event_writer.flush()\n","  File \"/usr/local/lib/python3.10/dist-packages/tensorboard/summary/writer/event_file_writer.py\", line 125, in flush\n","    self._async_writer.flush()\n","  File \"/usr/local/lib/python3.10/dist-packages/tensorboard/summary/writer/event_file_writer.py\", line 190, in flush\n","    self._writer.flush()\n","  File \"/usr/local/lib/python3.10/dist-packages/tensorboard/summary/writer/record_writer.py\", line 43, in flush\n","    self._writer.flush()\n","  File \"/usr/local/lib/python3.10/dist-packages/tensorflow/python/lib/io/file_io.py\", line 221, in flush\n","    self._writable_file.flush()\n","tensorflow.python.framework.errors_impl.FailedPreconditionError: Outputs/runs/Nov29_18-22-26_3ad3d6404bd0/events.out.tfevents.1701282205.3ad3d6404bd0.4587.0; Transport endpoint is not connected\n","\n","During handling of the above exception, another exception occurred:\n","\n","Traceback (most recent call last):\n","  File \"/usr/local/lib/python3.10/dist-packages/IPython/core/interactiveshell.py\", line 2099, in showtraceback\n","    stb = value._render_traceback_()\n","AttributeError: 'FailedPreconditionError' object has no attribute '_render_traceback_'\n","\n","During handling of the above exception, another exception occurred:\n","\n","Traceback (most recent call last):\n","  File \"/usr/local/lib/python3.10/dist-packages/IPython/core/ultratb.py\", line 1101, in get_records\n","    return _fixed_getinnerframes(etb, number_of_lines_of_context, tb_offset)\n","  File \"/usr/local/lib/python3.10/dist-packages/IPython/core/ultratb.py\", line 248, in wrapped\n","    return f(*args, **kwargs)\n","  File \"/usr/local/lib/python3.10/dist-packages/IPython/core/ultratb.py\", line 281, in _fixed_getinnerframes\n","    records = fix_frame_records_filenames(inspect.getinnerframes(etb, context))\n","  File \"/usr/lib/python3.10/inspect.py\", line 1662, in getinnerframes\n","    frameinfo = (tb.tb_frame,) + getframeinfo(tb, context)\n","  File \"/usr/lib/python3.10/inspect.py\", line 1620, in getframeinfo\n","    filename = getsourcefile(frame) or getfile(frame)\n","  File \"/usr/lib/python3.10/inspect.py\", line 829, in getsourcefile\n","    module = getmodule(object, filename)\n","  File \"/usr/lib/python3.10/inspect.py\", line 861, in getmodule\n","    file = getabsfile(object, _filename)\n","  File \"/usr/lib/python3.10/inspect.py\", line 845, in getabsfile\n","    return os.path.normcase(os.path.abspath(_filename))\n","  File \"/usr/lib/python3.10/posixpath.py\", line 384, in abspath\n","    cwd = os.getcwd()\n","OSError: [Errno 107] Transport endpoint is not connected\n","Traceback (most recent call last):\n","  File \"/usr/local/lib/python3.10/dist-packages/IPython/core/interactiveshell.py\", line 3553, in run_code\n","    exec(code_obj, self.user_global_ns, self.user_ns)\n","  File \"<ipython-input-11-79cc5d5f2588>\", line 2, in <cell line: 2>\n","    trainer.train()\n","  File \"/usr/local/lib/python3.10/dist-packages/transformers/trainer.py\", line 1555, in train\n","    return inner_training_loop(\n","  File \"/usr/local/lib/python3.10/dist-packages/transformers/trainer.py\", line 1922, in _inner_training_loop\n","    self._maybe_log_save_evaluate(tr_loss, model, trial, epoch, ignore_keys_for_eval)\n","  File \"/usr/local/lib/python3.10/dist-packages/transformers/trainer.py\", line 2257, in _maybe_log_save_evaluate\n","    self.log(logs)\n","  File \"/usr/local/lib/python3.10/dist-packages/transformers/trainer.py\", line 2645, in log\n","    self.control = self.callback_handler.on_log(self.args, self.state, self.control, logs)\n","  File \"/usr/local/lib/python3.10/dist-packages/transformers/trainer_callback.py\", line 400, in on_log\n","    return self.call_event(\"on_log\", args, state, control, logs=logs)\n","  File \"/usr/local/lib/python3.10/dist-packages/transformers/trainer_callback.py\", line 407, in call_event\n","    result = getattr(callback, event)(\n","  File \"/usr/local/lib/python3.10/dist-packages/transformers/integrations/integration_utils.py\", line 653, in on_log\n","    self.tb_writer.flush()\n","  File \"/usr/local/lib/python3.10/dist-packages/torch/utils/tensorboard/writer.py\", line 1233, in flush\n","    writer.flush()\n","  File \"/usr/local/lib/python3.10/dist-packages/torch/utils/tensorboard/writer.py\", line 146, in flush\n","    self.event_writer.flush()\n","  File \"/usr/local/lib/python3.10/dist-packages/tensorboard/summary/writer/event_file_writer.py\", line 125, in flush\n","    self._async_writer.flush()\n","  File \"/usr/local/lib/python3.10/dist-packages/tensorboard/summary/writer/event_file_writer.py\", line 190, in flush\n","    self._writer.flush()\n","  File \"/usr/local/lib/python3.10/dist-packages/tensorboard/summary/writer/record_writer.py\", line 43, in flush\n","    self._writer.flush()\n","  File \"/usr/local/lib/python3.10/dist-packages/tensorflow/python/lib/io/file_io.py\", line 221, in flush\n","    self._writable_file.flush()\n","tensorflow.python.framework.errors_impl.FailedPreconditionError: Outputs/runs/Nov29_18-22-26_3ad3d6404bd0/events.out.tfevents.1701282205.3ad3d6404bd0.4587.0; Transport endpoint is not connected\n","\n","During handling of the above exception, another exception occurred:\n","\n","Traceback (most recent call last):\n","  File \"/usr/local/lib/python3.10/dist-packages/IPython/core/interactiveshell.py\", line 2099, in showtraceback\n","    stb = value._render_traceback_()\n","AttributeError: 'FailedPreconditionError' object has no attribute '_render_traceback_'\n","\n","During handling of the above exception, another exception occurred:\n","\n","Traceback (most recent call last):\n","  File \"/usr/local/lib/python3.10/dist-packages/IPython/core/interactiveshell.py\", line 3473, in run_ast_nodes\n","    if (await self.run_code(code, result,  async_=asy)):\n","  File \"/usr/local/lib/python3.10/dist-packages/IPython/core/interactiveshell.py\", line 3575, in run_code\n","    self.showtraceback(running_compiled_code=True)\n","  File \"/usr/local/lib/python3.10/dist-packages/IPython/core/interactiveshell.py\", line 2101, in showtraceback\n","    stb = self.InteractiveTB.structured_traceback(etype,\n","  File \"/usr/local/lib/python3.10/dist-packages/IPython/core/ultratb.py\", line 1367, in structured_traceback\n","    return FormattedTB.structured_traceback(\n","  File \"/usr/local/lib/python3.10/dist-packages/IPython/core/ultratb.py\", line 1267, in structured_traceback\n","    return VerboseTB.structured_traceback(\n","  File \"/usr/local/lib/python3.10/dist-packages/IPython/core/ultratb.py\", line 1124, in structured_traceback\n","    formatted_exception = self.format_exception_as_a_whole(etype, evalue, etb, number_of_lines_of_context,\n","  File \"/usr/local/lib/python3.10/dist-packages/IPython/core/ultratb.py\", line 1082, in format_exception_as_a_whole\n","    last_unique, recursion_repeat = find_recursion(orig_etype, evalue, records)\n","  File \"/usr/local/lib/python3.10/dist-packages/IPython/core/ultratb.py\", line 382, in find_recursion\n","    return len(records), 0\n","TypeError: object of type 'NoneType' has no len()\n","\n","During handling of the above exception, another exception occurred:\n","\n","Traceback (most recent call last):\n","  File \"/usr/local/lib/python3.10/dist-packages/IPython/core/interactiveshell.py\", line 2099, in showtraceback\n","    stb = value._render_traceback_()\n","AttributeError: 'TypeError' object has no attribute '_render_traceback_'\n","\n","During handling of the above exception, another exception occurred:\n","\n","Traceback (most recent call last):\n","  File \"/usr/local/lib/python3.10/dist-packages/IPython/core/ultratb.py\", line 1101, in get_records\n","    return _fixed_getinnerframes(etb, number_of_lines_of_context, tb_offset)\n","  File \"/usr/local/lib/python3.10/dist-packages/IPython/core/ultratb.py\", line 248, in wrapped\n","    return f(*args, **kwargs)\n","  File \"/usr/local/lib/python3.10/dist-packages/IPython/core/ultratb.py\", line 281, in _fixed_getinnerframes\n","    records = fix_frame_records_filenames(inspect.getinnerframes(etb, context))\n","  File \"/usr/lib/python3.10/inspect.py\", line 1662, in getinnerframes\n","    frameinfo = (tb.tb_frame,) + getframeinfo(tb, context)\n","  File \"/usr/lib/python3.10/inspect.py\", line 1620, in getframeinfo\n","    filename = getsourcefile(frame) or getfile(frame)\n","  File \"/usr/lib/python3.10/inspect.py\", line 829, in getsourcefile\n","    module = getmodule(object, filename)\n","  File \"/usr/lib/python3.10/inspect.py\", line 861, in getmodule\n","    file = getabsfile(object, _filename)\n","  File \"/usr/lib/python3.10/inspect.py\", line 845, in getabsfile\n","    return os.path.normcase(os.path.abspath(_filename))\n","  File \"/usr/lib/python3.10/posixpath.py\", line 384, in abspath\n","    cwd = os.getcwd()\n","OSError: [Errno 107] Transport endpoint is not connected\n","Traceback (most recent call last):\n","  File \"/usr/local/lib/python3.10/dist-packages/IPython/core/interactiveshell.py\", line 3553, in run_code\n","    exec(code_obj, self.user_global_ns, self.user_ns)\n","  File \"<ipython-input-11-79cc5d5f2588>\", line 2, in <cell line: 2>\n","    trainer.train()\n","  File \"/usr/local/lib/python3.10/dist-packages/transformers/trainer.py\", line 1555, in train\n","    return inner_training_loop(\n","  File \"/usr/local/lib/python3.10/dist-packages/transformers/trainer.py\", line 1922, in _inner_training_loop\n","    self._maybe_log_save_evaluate(tr_loss, model, trial, epoch, ignore_keys_for_eval)\n","  File \"/usr/local/lib/python3.10/dist-packages/transformers/trainer.py\", line 2257, in _maybe_log_save_evaluate\n","    self.log(logs)\n","  File \"/usr/local/lib/python3.10/dist-packages/transformers/trainer.py\", line 2645, in log\n","    self.control = self.callback_handler.on_log(self.args, self.state, self.control, logs)\n","  File \"/usr/local/lib/python3.10/dist-packages/transformers/trainer_callback.py\", line 400, in on_log\n","    return self.call_event(\"on_log\", args, state, control, logs=logs)\n","  File \"/usr/local/lib/python3.10/dist-packages/transformers/trainer_callback.py\", line 407, in call_event\n","    result = getattr(callback, event)(\n","  File \"/usr/local/lib/python3.10/dist-packages/transformers/integrations/integration_utils.py\", line 653, in on_log\n","    self.tb_writer.flush()\n","  File \"/usr/local/lib/python3.10/dist-packages/torch/utils/tensorboard/writer.py\", line 1233, in flush\n","    writer.flush()\n","  File \"/usr/local/lib/python3.10/dist-packages/torch/utils/tensorboard/writer.py\", line 146, in flush\n","    self.event_writer.flush()\n","  File \"/usr/local/lib/python3.10/dist-packages/tensorboard/summary/writer/event_file_writer.py\", line 125, in flush\n","    self._async_writer.flush()\n","  File \"/usr/local/lib/python3.10/dist-packages/tensorboard/summary/writer/event_file_writer.py\", line 190, in flush\n","    self._writer.flush()\n","  File \"/usr/local/lib/python3.10/dist-packages/tensorboard/summary/writer/record_writer.py\", line 43, in flush\n","    self._writer.flush()\n","  File \"/usr/local/lib/python3.10/dist-packages/tensorflow/python/lib/io/file_io.py\", line 221, in flush\n","    self._writable_file.flush()\n","tensorflow.python.framework.errors_impl.FailedPreconditionError: Outputs/runs/Nov29_18-22-26_3ad3d6404bd0/events.out.tfevents.1701282205.3ad3d6404bd0.4587.0; Transport endpoint is not connected\n","\n","During handling of the above exception, another exception occurred:\n","\n","Traceback (most recent call last):\n","  File \"/usr/local/lib/python3.10/dist-packages/IPython/core/interactiveshell.py\", line 2099, in showtraceback\n","    stb = value._render_traceback_()\n","AttributeError: 'FailedPreconditionError' object has no attribute '_render_traceback_'\n","\n","During handling of the above exception, another exception occurred:\n","\n","Traceback (most recent call last):\n","  File \"/usr/local/lib/python3.10/dist-packages/IPython/core/interactiveshell.py\", line 3473, in run_ast_nodes\n","    if (await self.run_code(code, result,  async_=asy)):\n","  File \"/usr/local/lib/python3.10/dist-packages/IPython/core/interactiveshell.py\", line 3575, in run_code\n","    self.showtraceback(running_compiled_code=True)\n","  File \"/usr/local/lib/python3.10/dist-packages/IPython/core/interactiveshell.py\", line 2101, in showtraceback\n","    stb = self.InteractiveTB.structured_traceback(etype,\n","  File \"/usr/local/lib/python3.10/dist-packages/IPython/core/ultratb.py\", line 1367, in structured_traceback\n","    return FormattedTB.structured_traceback(\n","  File \"/usr/local/lib/python3.10/dist-packages/IPython/core/ultratb.py\", line 1267, in structured_traceback\n","    return VerboseTB.structured_traceback(\n","  File \"/usr/local/lib/python3.10/dist-packages/IPython/core/ultratb.py\", line 1124, in structured_traceback\n","    formatted_exception = self.format_exception_as_a_whole(etype, evalue, etb, number_of_lines_of_context,\n","  File \"/usr/local/lib/python3.10/dist-packages/IPython/core/ultratb.py\", line 1082, in format_exception_as_a_whole\n","    last_unique, recursion_repeat = find_recursion(orig_etype, evalue, records)\n","  File \"/usr/local/lib/python3.10/dist-packages/IPython/core/ultratb.py\", line 382, in find_recursion\n","    return len(records), 0\n","TypeError: object of type 'NoneType' has no len()\n","\n","During handling of the above exception, another exception occurred:\n","\n","Traceback (most recent call last):\n","  File \"/usr/local/lib/python3.10/dist-packages/IPython/core/interactiveshell.py\", line 2099, in showtraceback\n","    stb = value._render_traceback_()\n","AttributeError: 'TypeError' object has no attribute '_render_traceback_'\n","\n","During handling of the above exception, another exception occurred:\n","\n","Traceback (most recent call last):\n","  File \"/usr/local/lib/python3.10/dist-packages/IPython/core/interactiveshell.py\", line 3030, in _run_cell\n","    return runner(coro)\n","  File \"/usr/local/lib/python3.10/dist-packages/IPython/core/async_helpers.py\", line 78, in _pseudo_sync_runner\n","    coro.send(None)\n","  File \"/usr/local/lib/python3.10/dist-packages/IPython/core/interactiveshell.py\", line 3257, in run_cell_async\n","    has_raised = await self.run_ast_nodes(code_ast.body, cell_name,\n","  File \"/usr/local/lib/python3.10/dist-packages/IPython/core/interactiveshell.py\", line 3492, in run_ast_nodes\n","    self.showtraceback()\n","  File \"/usr/local/lib/python3.10/dist-packages/IPython/core/interactiveshell.py\", line 2101, in showtraceback\n","    stb = self.InteractiveTB.structured_traceback(etype,\n","  File \"/usr/local/lib/python3.10/dist-packages/IPython/core/ultratb.py\", line 1367, in structured_traceback\n","    return FormattedTB.structured_traceback(\n","  File \"/usr/local/lib/python3.10/dist-packages/IPython/core/ultratb.py\", line 1267, in structured_traceback\n","    return VerboseTB.structured_traceback(\n","  File \"/usr/local/lib/python3.10/dist-packages/IPython/core/ultratb.py\", line 1142, in structured_traceback\n","    formatted_exceptions += self.format_exception_as_a_whole(etype, evalue, etb, lines_of_context,\n","  File \"/usr/local/lib/python3.10/dist-packages/IPython/core/ultratb.py\", line 1082, in format_exception_as_a_whole\n","    last_unique, recursion_repeat = find_recursion(orig_etype, evalue, records)\n","  File \"/usr/local/lib/python3.10/dist-packages/IPython/core/ultratb.py\", line 382, in find_recursion\n","    return len(records), 0\n","TypeError: object of type 'NoneType' has no len()\n","\n","During handling of the above exception, another exception occurred:\n","\n","Traceback (most recent call last):\n","  File \"/usr/local/lib/python3.10/dist-packages/IPython/core/interactiveshell.py\", line 2099, in showtraceback\n","    stb = value._render_traceback_()\n","AttributeError: 'TypeError' object has no attribute '_render_traceback_'\n","\n","During handling of the above exception, another exception occurred:\n","\n","Traceback (most recent call last):\n","  File \"/usr/local/lib/python3.10/dist-packages/IPython/core/ultratb.py\", line 1101, in get_records\n","    return _fixed_getinnerframes(etb, number_of_lines_of_context, tb_offset)\n","  File \"/usr/local/lib/python3.10/dist-packages/IPython/core/ultratb.py\", line 248, in wrapped\n","    return f(*args, **kwargs)\n","  File \"/usr/local/lib/python3.10/dist-packages/IPython/core/ultratb.py\", line 281, in _fixed_getinnerframes\n","    records = fix_frame_records_filenames(inspect.getinnerframes(etb, context))\n","  File \"/usr/lib/python3.10/inspect.py\", line 1662, in getinnerframes\n","    frameinfo = (tb.tb_frame,) + getframeinfo(tb, context)\n","  File \"/usr/lib/python3.10/inspect.py\", line 1620, in getframeinfo\n","    filename = getsourcefile(frame) or getfile(frame)\n","  File \"/usr/lib/python3.10/inspect.py\", line 829, in getsourcefile\n","    module = getmodule(object, filename)\n","  File \"/usr/lib/python3.10/inspect.py\", line 861, in getmodule\n","    file = getabsfile(object, _filename)\n","  File \"/usr/lib/python3.10/inspect.py\", line 845, in getabsfile\n","    return os.path.normcase(os.path.abspath(_filename))\n","  File \"/usr/lib/python3.10/posixpath.py\", line 384, in abspath\n","    cwd = os.getcwd()\n","OSError: [Errno 107] Transport endpoint is not connected\n"]}],"source":["os.environ['WANDB_SILENT']=\"true\"\n","trainer.train()"]},{"cell_type":"code","execution_count":null,"metadata":{"colab":{"background_save":true},"id":"hYQsy4zYh2zY","outputId":"5c48ca0b-7b81-4342-a070-342797858d67"},"outputs":[{"name":"stderr","output_type":"stream","text":["ERROR:root:Internal Python error in the inspect module.\n","Below is the traceback from this internal error.\n","\n","ERROR:root:Internal Python error in the inspect module.\n","Below is the traceback from this internal error.\n","\n","ERROR:root:Internal Python error in the inspect module.\n","Below is the traceback from this internal error.\n","\n"]},{"name":"stdout","output_type":"stream","text":["Traceback (most recent call last):\n","  File \"/usr/local/lib/python3.10/dist-packages/IPython/core/interactiveshell.py\", line 3553, in run_code\n","    exec(code_obj, self.user_global_ns, self.user_ns)\n","  File \"<ipython-input-11-296d37a19d47>\", line 2, in <cell line: 2>\n","    trainer.save_model(f\"{outputDir}/base-drop-20k\")\n","  File \"/usr/local/lib/python3.10/dist-packages/transformers/trainer.py\", line 2843, in save_model\n","    self._save(output_dir)\n","  File \"/usr/local/lib/python3.10/dist-packages/transformers/trainer.py\", line 2880, in _save\n","    os.makedirs(output_dir, exist_ok=True)\n","  File \"/usr/lib/python3.10/os.py\", line 215, in makedirs\n","    makedirs(head, exist_ok=exist_ok)\n","  File \"/usr/lib/python3.10/os.py\", line 225, in makedirs\n","    mkdir(name, mode)\n","OSError: [Errno 107] Transport endpoint is not connected: './Outputs'\n","\n","During handling of the above exception, another exception occurred:\n","\n","Traceback (most recent call last):\n","  File \"/usr/local/lib/python3.10/dist-packages/IPython/core/interactiveshell.py\", line 2099, in showtraceback\n","    stb = value._render_traceback_()\n","AttributeError: 'OSError' object has no attribute '_render_traceback_'\n","\n","During handling of the above exception, another exception occurred:\n","\n","Traceback (most recent call last):\n","  File \"/usr/local/lib/python3.10/dist-packages/IPython/core/ultratb.py\", line 1101, in get_records\n","    return _fixed_getinnerframes(etb, number_of_lines_of_context, tb_offset)\n","  File \"/usr/local/lib/python3.10/dist-packages/IPython/core/ultratb.py\", line 248, in wrapped\n","    return f(*args, **kwargs)\n","  File \"/usr/local/lib/python3.10/dist-packages/IPython/core/ultratb.py\", line 281, in _fixed_getinnerframes\n","    records = fix_frame_records_filenames(inspect.getinnerframes(etb, context))\n","  File \"/usr/lib/python3.10/inspect.py\", line 1662, in getinnerframes\n","    frameinfo = (tb.tb_frame,) + getframeinfo(tb, context)\n","  File \"/usr/lib/python3.10/inspect.py\", line 1620, in getframeinfo\n","    filename = getsourcefile(frame) or getfile(frame)\n","  File \"/usr/lib/python3.10/inspect.py\", line 829, in getsourcefile\n","    module = getmodule(object, filename)\n","  File \"/usr/lib/python3.10/inspect.py\", line 861, in getmodule\n","    file = getabsfile(object, _filename)\n","  File \"/usr/lib/python3.10/inspect.py\", line 845, in getabsfile\n","    return os.path.normcase(os.path.abspath(_filename))\n","  File \"/usr/lib/python3.10/posixpath.py\", line 384, in abspath\n","    cwd = os.getcwd()\n","OSError: [Errno 107] Transport endpoint is not connected\n","Traceback (most recent call last):\n","  File \"/usr/local/lib/python3.10/dist-packages/IPython/core/interactiveshell.py\", line 3553, in run_code\n","    exec(code_obj, self.user_global_ns, self.user_ns)\n","  File \"<ipython-input-11-296d37a19d47>\", line 2, in <cell line: 2>\n","    trainer.save_model(f\"{outputDir}/base-drop-20k\")\n","  File \"/usr/local/lib/python3.10/dist-packages/transformers/trainer.py\", line 2843, in save_model\n","    self._save(output_dir)\n","  File \"/usr/local/lib/python3.10/dist-packages/transformers/trainer.py\", line 2880, in _save\n","    os.makedirs(output_dir, exist_ok=True)\n","  File \"/usr/lib/python3.10/os.py\", line 215, in makedirs\n","    makedirs(head, exist_ok=exist_ok)\n","  File \"/usr/lib/python3.10/os.py\", line 225, in makedirs\n","    mkdir(name, mode)\n","OSError: [Errno 107] Transport endpoint is not connected: './Outputs'\n","\n","During handling of the above exception, another exception occurred:\n","\n","Traceback (most recent call last):\n","  File \"/usr/local/lib/python3.10/dist-packages/IPython/core/interactiveshell.py\", line 2099, in showtraceback\n","    stb = value._render_traceback_()\n","AttributeError: 'OSError' object has no attribute '_render_traceback_'\n","\n","During handling of the above exception, another exception occurred:\n","\n","Traceback (most recent call last):\n","  File \"/usr/local/lib/python3.10/dist-packages/IPython/core/interactiveshell.py\", line 3473, in run_ast_nodes\n","    if (await self.run_code(code, result,  async_=asy)):\n","  File \"/usr/local/lib/python3.10/dist-packages/IPython/core/interactiveshell.py\", line 3575, in run_code\n","    self.showtraceback(running_compiled_code=True)\n","  File \"/usr/local/lib/python3.10/dist-packages/IPython/core/interactiveshell.py\", line 2101, in showtraceback\n","    stb = self.InteractiveTB.structured_traceback(etype,\n","  File \"/usr/local/lib/python3.10/dist-packages/IPython/core/ultratb.py\", line 1367, in structured_traceback\n","    return FormattedTB.structured_traceback(\n","  File \"/usr/local/lib/python3.10/dist-packages/IPython/core/ultratb.py\", line 1267, in structured_traceback\n","    return VerboseTB.structured_traceback(\n","  File \"/usr/local/lib/python3.10/dist-packages/IPython/core/ultratb.py\", line 1124, in structured_traceback\n","    formatted_exception = self.format_exception_as_a_whole(etype, evalue, etb, number_of_lines_of_context,\n","  File \"/usr/local/lib/python3.10/dist-packages/IPython/core/ultratb.py\", line 1082, in format_exception_as_a_whole\n","    last_unique, recursion_repeat = find_recursion(orig_etype, evalue, records)\n","  File \"/usr/local/lib/python3.10/dist-packages/IPython/core/ultratb.py\", line 382, in find_recursion\n","    return len(records), 0\n","TypeError: object of type 'NoneType' has no len()\n","\n","During handling of the above exception, another exception occurred:\n","\n","Traceback (most recent call last):\n","  File \"/usr/local/lib/python3.10/dist-packages/IPython/core/interactiveshell.py\", line 2099, in showtraceback\n","    stb = value._render_traceback_()\n","AttributeError: 'TypeError' object has no attribute '_render_traceback_'\n","\n","During handling of the above exception, another exception occurred:\n","\n","Traceback (most recent call last):\n","  File \"/usr/local/lib/python3.10/dist-packages/IPython/core/ultratb.py\", line 1101, in get_records\n","    return _fixed_getinnerframes(etb, number_of_lines_of_context, tb_offset)\n","  File \"/usr/local/lib/python3.10/dist-packages/IPython/core/ultratb.py\", line 248, in wrapped\n","    return f(*args, **kwargs)\n","  File \"/usr/local/lib/python3.10/dist-packages/IPython/core/ultratb.py\", line 281, in _fixed_getinnerframes\n","    records = fix_frame_records_filenames(inspect.getinnerframes(etb, context))\n","  File \"/usr/lib/python3.10/inspect.py\", line 1662, in getinnerframes\n","    frameinfo = (tb.tb_frame,) + getframeinfo(tb, context)\n","  File \"/usr/lib/python3.10/inspect.py\", line 1620, in getframeinfo\n","    filename = getsourcefile(frame) or getfile(frame)\n","  File \"/usr/lib/python3.10/inspect.py\", line 829, in getsourcefile\n","    module = getmodule(object, filename)\n","  File \"/usr/lib/python3.10/inspect.py\", line 861, in getmodule\n","    file = getabsfile(object, _filename)\n","  File \"/usr/lib/python3.10/inspect.py\", line 845, in getabsfile\n","    return os.path.normcase(os.path.abspath(_filename))\n","  File \"/usr/lib/python3.10/posixpath.py\", line 384, in abspath\n","    cwd = os.getcwd()\n","OSError: [Errno 107] Transport endpoint is not connected\n","Traceback (most recent call last):\n","  File \"/usr/local/lib/python3.10/dist-packages/IPython/core/interactiveshell.py\", line 3553, in run_code\n","    exec(code_obj, self.user_global_ns, self.user_ns)\n","  File \"<ipython-input-11-296d37a19d47>\", line 2, in <cell line: 2>\n","    trainer.save_model(f\"{outputDir}/base-drop-20k\")\n","  File \"/usr/local/lib/python3.10/dist-packages/transformers/trainer.py\", line 2843, in save_model\n","    self._save(output_dir)\n","  File \"/usr/local/lib/python3.10/dist-packages/transformers/trainer.py\", line 2880, in _save\n","    os.makedirs(output_dir, exist_ok=True)\n","  File \"/usr/lib/python3.10/os.py\", line 215, in makedirs\n","    makedirs(head, exist_ok=exist_ok)\n","  File \"/usr/lib/python3.10/os.py\", line 225, in makedirs\n","    mkdir(name, mode)\n","OSError: [Errno 107] Transport endpoint is not connected: './Outputs'\n","\n","During handling of the above exception, another exception occurred:\n","\n","Traceback (most recent call last):\n","  File \"/usr/local/lib/python3.10/dist-packages/IPython/core/interactiveshell.py\", line 2099, in showtraceback\n","    stb = value._render_traceback_()\n","AttributeError: 'OSError' object has no attribute '_render_traceback_'\n","\n","During handling of the above exception, another exception occurred:\n","\n","Traceback (most recent call last):\n","  File \"/usr/local/lib/python3.10/dist-packages/IPython/core/interactiveshell.py\", line 3473, in run_ast_nodes\n","    if (await self.run_code(code, result,  async_=asy)):\n","  File \"/usr/local/lib/python3.10/dist-packages/IPython/core/interactiveshell.py\", line 3575, in run_code\n","    self.showtraceback(running_compiled_code=True)\n","  File \"/usr/local/lib/python3.10/dist-packages/IPython/core/interactiveshell.py\", line 2101, in showtraceback\n","    stb = self.InteractiveTB.structured_traceback(etype,\n","  File \"/usr/local/lib/python3.10/dist-packages/IPython/core/ultratb.py\", line 1367, in structured_traceback\n","    return FormattedTB.structured_traceback(\n","  File \"/usr/local/lib/python3.10/dist-packages/IPython/core/ultratb.py\", line 1267, in structured_traceback\n","    return VerboseTB.structured_traceback(\n","  File \"/usr/local/lib/python3.10/dist-packages/IPython/core/ultratb.py\", line 1124, in structured_traceback\n","    formatted_exception = self.format_exception_as_a_whole(etype, evalue, etb, number_of_lines_of_context,\n","  File \"/usr/local/lib/python3.10/dist-packages/IPython/core/ultratb.py\", line 1082, in format_exception_as_a_whole\n","    last_unique, recursion_repeat = find_recursion(orig_etype, evalue, records)\n","  File \"/usr/local/lib/python3.10/dist-packages/IPython/core/ultratb.py\", line 382, in find_recursion\n","    return len(records), 0\n","TypeError: object of type 'NoneType' has no len()\n","\n","During handling of the above exception, another exception occurred:\n","\n","Traceback (most recent call last):\n","  File \"/usr/local/lib/python3.10/dist-packages/IPython/core/interactiveshell.py\", line 2099, in showtraceback\n","    stb = value._render_traceback_()\n","AttributeError: 'TypeError' object has no attribute '_render_traceback_'\n","\n","During handling of the above exception, another exception occurred:\n","\n","Traceback (most recent call last):\n","  File \"/usr/local/lib/python3.10/dist-packages/IPython/core/interactiveshell.py\", line 3030, in _run_cell\n","    return runner(coro)\n","  File \"/usr/local/lib/python3.10/dist-packages/IPython/core/async_helpers.py\", line 78, in _pseudo_sync_runner\n","    coro.send(None)\n","  File \"/usr/local/lib/python3.10/dist-packages/IPython/core/interactiveshell.py\", line 3257, in run_cell_async\n","    has_raised = await self.run_ast_nodes(code_ast.body, cell_name,\n","  File \"/usr/local/lib/python3.10/dist-packages/IPython/core/interactiveshell.py\", line 3492, in run_ast_nodes\n","    self.showtraceback()\n","  File \"/usr/local/lib/python3.10/dist-packages/IPython/core/interactiveshell.py\", line 2101, in showtraceback\n","    stb = self.InteractiveTB.structured_traceback(etype,\n","  File \"/usr/local/lib/python3.10/dist-packages/IPython/core/ultratb.py\", line 1367, in structured_traceback\n","    return FormattedTB.structured_traceback(\n","  File \"/usr/local/lib/python3.10/dist-packages/IPython/core/ultratb.py\", line 1267, in structured_traceback\n","    return VerboseTB.structured_traceback(\n","  File \"/usr/local/lib/python3.10/dist-packages/IPython/core/ultratb.py\", line 1142, in structured_traceback\n","    formatted_exceptions += self.format_exception_as_a_whole(etype, evalue, etb, lines_of_context,\n","  File \"/usr/local/lib/python3.10/dist-packages/IPython/core/ultratb.py\", line 1082, in format_exception_as_a_whole\n","    last_unique, recursion_repeat = find_recursion(orig_etype, evalue, records)\n","  File \"/usr/local/lib/python3.10/dist-packages/IPython/core/ultratb.py\", line 382, in find_recursion\n","    return len(records), 0\n","TypeError: object of type 'NoneType' has no len()\n","\n","During handling of the above exception, another exception occurred:\n","\n","Traceback (most recent call last):\n","  File \"/usr/local/lib/python3.10/dist-packages/IPython/core/interactiveshell.py\", line 2099, in showtraceback\n","    stb = value._render_traceback_()\n","AttributeError: 'TypeError' object has no attribute '_render_traceback_'\n","\n","During handling of the above exception, another exception occurred:\n","\n","Traceback (most recent call last):\n","  File \"/usr/local/lib/python3.10/dist-packages/IPython/core/ultratb.py\", line 1101, in get_records\n","    return _fixed_getinnerframes(etb, number_of_lines_of_context, tb_offset)\n","  File \"/usr/local/lib/python3.10/dist-packages/IPython/core/ultratb.py\", line 248, in wrapped\n","    return f(*args, **kwargs)\n","  File \"/usr/local/lib/python3.10/dist-packages/IPython/core/ultratb.py\", line 281, in _fixed_getinnerframes\n","    records = fix_frame_records_filenames(inspect.getinnerframes(etb, context))\n","  File \"/usr/lib/python3.10/inspect.py\", line 1662, in getinnerframes\n","    frameinfo = (tb.tb_frame,) + getframeinfo(tb, context)\n","  File \"/usr/lib/python3.10/inspect.py\", line 1620, in getframeinfo\n","    filename = getsourcefile(frame) or getfile(frame)\n","  File \"/usr/lib/python3.10/inspect.py\", line 829, in getsourcefile\n","    module = getmodule(object, filename)\n","  File \"/usr/lib/python3.10/inspect.py\", line 861, in getmodule\n","    file = getabsfile(object, _filename)\n","  File \"/usr/lib/python3.10/inspect.py\", line 845, in getabsfile\n","    return os.path.normcase(os.path.abspath(_filename))\n","  File \"/usr/lib/python3.10/posixpath.py\", line 384, in abspath\n","    cwd = os.getcwd()\n","OSError: [Errno 107] Transport endpoint is not connected\n"]}],"source":["outputDir = \"./Outputs\"\n","trainer.save_model(f\"{outputDir}/base-drop-20k\")"]}],"metadata":{"accelerator":"GPU","colab":{"provenance":[]},"kernelspec":{"display_name":"Python 3 (ipykernel)","language":"python","name":"python3"},"language_info":{"codemirror_mode":{"name":"ipython","version":3},"file_extension":".py","mimetype":"text/x-python","name":"python","nbconvert_exporter":"python","pygments_lexer":"ipython3","version":"3.10.12"}},"nbformat":4,"nbformat_minor":0}